# -catch.-122
//Несколько блоков catch. Обработка исключений #122
void Foo(int value)
{
	if (value < 0)
	{		
		//throw exception("Число меньше нуля");
		 throw  "Число меньше нуля";//блок 2, бросаем строку, попадаем во 2 блок catch
	}
	if (value==0)
	{
		throw exception("Число равно нулю");//блок 1 отработает
	}
	if (value == 1)
	{
		throw 1;//условие, которое не подошло ни под один catch  тк нет соотв-го типа данных
		//и оно попадет в catch (...)
	}
	cout << "Переменная= " << value << endl;
}
int main()
{
	setlocale(LC_ALL, "ru");
	try
	{
		Foo(1);//если сюда бросили целое число, то и ловить ошибку в catch н.
		//с целым числом. Сюда м. передать любое число
		//т е catch (const int ex). Если строку то catch (const char *ex)
	}
	catch (exception& ex)//(const exception &ex)-для классов исключений. это более универсальное решение
	{
		cout << "Блок 1 Мы поймали " << ex.what() << endl;
	}
	catch (const char *ex)
	{
		cout << "Блок 2 Мы поймали " << ex << endl;

	}
	catch (...)//сюда попадают все throw типы данных которых не указаны, т е все подряд
		//если такой catch поставить перед другими, т е выше, то они работать не будут,
		//это исключение перекроет все подряд
	{
		cout << "Что-то пошло не так!" << endl;
	}

	return 0;
}
